<?xml version="1.0" encoding="utf-8"?>
<!-- This URDF was automatically created by SolidWorks to URDF Exporter! Originally created by Stephen Brawner (brawner@gmail.com) 
     Commit Version: 1.6.0-4-g7f85cfe  Build Version: 1.6.7995.38578
     For more information, please see http://wiki.ros.org/sw_urdf_exporter -->
<robot
  name="boatcleaninge">
  <link
    name="baseboatclening">
    <inertial>
      <origin
        xyz="-0.04784 2.4633E-05 0.14963"
        rpy="0 0 0" />
      <mass
        value="13.329" />
      <inertia
        ixx="0.12461"
        ixy="1.1446E-06"
        ixz="-0.0014794"
        iyy="0.095916"
        iyz="1.0063E-05"
        izz="0.13623" />
    </inertial>
    <visual>
      <origin
        xyz="0 0 0"
        rpy="0 0 0" />
      <geometry>
        <mesh
          filename="package://boatcleaninge/meshes/baseboatclening.STL" />
      </geometry>
      <material
        name="">
        <color
          rgba="1 1 1 1" />
      </material>
    </visual>
    <collision>
      <origin
        xyz="0 0 0"
        rpy="0 0 0" />
      <geometry>
        <mesh
          filename="package://boatcleaninge/meshes/baseboatclening.STL" />
      </geometry>
    </collision>
  </link>
  <link
    name="axegauche">
    <inertial>
      <origin
        xyz="0.0098838 5.5598E-05 0.0036051"
        rpy="0 0 0" />
      <mass
        value="0.2016" />
      <inertia
        ixx="0.00021153"
        ixy="-1.977E-07"
        ixz="-2.0576E-06"
        iyy="0.00016202"
        iyz="-9.0328E-07"
        izz="0.00013067" />
    </inertial>
    <visual>
      <origin
        xyz="0 0 0"
        rpy="0 0 0" />
      <geometry>
        <mesh
          filename="package://boatcleaninge/meshes/axegauche.STL" />
      </geometry>
      <material
        name="">
        <color
          rgba="0.79216 0.81961 0.93333 1" />
      </material>
    </visual>
    <collision>
      <origin
        xyz="0 0 0"
        rpy="0 0 0" />
      <geometry>
        <mesh
          filename="package://boatcleaninge/meshes/axegauche.STL" />
      </geometry>
    </collision>
  </link>
  <joint
    name="axegauchejoint"
    type="fixed">
    <origin
      xyz="-0.30981 0.39873 -0.056"
      rpy="0 0 0" />
    <parent
      link="baseboatclening" />
    <child
      link="axegauche" />
    <axis
      xyz="0 0 0" />
  </joint>
  <link
    name="fangauche">
    <inertial>
      <origin
        xyz="0.0121880649596053 -1.96166671795339E-09 4.45801810883273E-08"
        rpy="0 0 0" />
      <mass
        value="0.00795785659641835" />
      <inertia
        ixx="3.72710558894494E-06"
        ixy="2.12970220916509E-13"
        ixz="-8.34019263853851E-13"
        iyy="2.3933165516727E-06"
        iyz="-4.61638273541746E-10"
        izz="2.39447831194735E-06" />
    </inertial>
    <visual>
      <origin
        xyz="0 0 0"
        rpy="0 0 0" />
      <geometry>
        <mesh
          filename="package://boatcleaninge/meshes/fangauche.STL" />
      </geometry>
      <material
        name="">
        <color
          rgba="0.792156862745098 0.819607843137255 0.933333333333333 1" />
      </material>
    </visual>
    <collision>
      <origin
        xyz="0 0 0"
        rpy="0 0 0" />
      <geometry>
        <mesh
          filename="package://boatcleaninge/meshes/fangauche.STL" />
      </geometry>
    </collision>
  </link>
  <joint
    name="fangauchejoint"
    type="continuous">
    <origin
      xyz="0 0 0"
      rpy="0 0 0" />
    <parent
      link="axegauche" />
    <child
      link="fangauche" />
    <axis
      xyz="1 0 0" />
  </joint>
  <link
    name="axedroit">
    <inertial>
      <origin
        xyz="0 0 0"
        rpy="0 0 0" />
      <mass
        value="0" />
      <inertia
        ixx="0"
        ixy="0"
        ixz="0"
        iyy="0"
        iyz="0"
        izz="0" />
    </inertial>
    <visual>
      <origin
        xyz="0 0 0"
        rpy="0 0 0" />
      <geometry>
        <mesh
          filename="package://boatcleaninge/meshes/axedroit.STL" />
      </geometry>
      <material
        name="">
        <color
          rgba="1 1 1 1" />
      </material>
    </visual>
    <collision>
      <origin
        xyz="0 0 0"
        rpy="0 0 0" />
      <geometry>
        <mesh
          filename="package://boatcleaninge/meshes/axedroit.STL" />
      </geometry>
    </collision>
  </link>
  <joint
    name="axedroitjoint"
    type="fixed">
    <origin
      xyz="-0.3088 -0.40127 -0.056"
      rpy="0 0 0" />
    <parent
      link="baseboatclening" />
    <child
      link="axedroit" />
    <axis
      xyz="0 0 0" />
  </joint>
  <link
    name="fandroit">
    <inertial>
      <origin
        xyz="0.0111720649596023 -1.96166084764915E-09 4.45801802140267E-08"
        rpy="0 0 0" />
      <mass
        value="0.00795785659641851" />
      <inertia
        ixx="3.72710558894501E-06"
        ixy="2.12970221640292E-13"
        ixz="-8.34019269810521E-13"
        iyy="2.39331655167276E-06"
        iyz="-4.61638273471348E-10"
        izz="2.39447831194736E-06" />
    </inertial>
    <visual>
      <origin
        xyz="0 0 0"
        rpy="0 0 0" />
      <geometry>
        <mesh
          filename="package://boatcleaninge/meshes/fandroit.STL" />
      </geometry>
      <material
        name="">
        <color
          rgba="0.792156862745098 0.819607843137255 0.933333333333333 1" />
      </material>
    </visual>
    <collision>
      <origin
        xyz="0 0 0"
        rpy="0 0 0" />
      <geometry>
        <mesh
          filename="package://boatcleaninge/meshes/fandroit.STL" />
      </geometry>
    </collision>
  </link>
  <joint
    name="fandroitjoint"
    type="continuous">
    <origin
      xyz="0 0 0"
      rpy="0 0 0" />
    <parent
      link="axedroit" />
    <child
      link="fandroit" />
    <axis
      xyz="1 0 0" />
  </joint>
</robot>